Workbook

Sheet Вертикальные пропорции
A1: Номер яч | B1: площадь фасада | C1: площадь ячейки | D1: коэф | E1: итог | G1: длина фасада 1 | H1: Этажность 1 | I1: длина фасада 2 | J1: Этажность 2 | K1: длина фасада 3 | L1: Этажность 3 | M1: длина фасада 4 | N1: Этажность 4 | O1: примечание
A2: 1 | B2: =G2*H2*3+I2*J2*3+K2*L2*3+M2*N2*3 | C2: 2823 | D2: =B2/C2 | E2: =IF(B2=0,"Нет",IF(AND(D2>=1.3,D2<=2),"Высокий",IF(AND(D2>=0.6,D2<1.3),"Средний","Низкий")))
A3: 2 | B3: =G3*H3*3+I3*J3*3+K3*L3*3+M3*N3*3 | C3: 1462 | D3: =B3/C3 | E3: =IF(B3=0,"Нет",IF(AND(D3>=1.3,D3<=2),"Высокий",IF(AND(D3>=0.6,D3<1.3),"Средний","Низкий"))) | G3: 79 | H3: 17
A4: 3 | B4: =G4*H4*3+I4*J4*3+K4*L4*3+M4*N4*3 | C4: 3806 | D4: =B4/C4 | E4: =IF(B4=0,"Нет",IF(AND(D4>=1.3,D4<=2),"Высокий",IF(AND(D4>=0.6,D4<1.3),"Средний","Низкий"))) | G4: 18 | H4: 17 | I4: 70 | J4: 16
A5: 4 | B5: =G5*H5*3+I5*J5*3+K5*L5*3+M5*N5*3 | C5: 4012 | D5: =B5/C5 | E5: =IF(B5=0,"Нет",IF(AND(D5>=1.3,D5<=2),"Высокий",IF(AND(D5>=0.6,D5<1.3),"Средний","Низкий"))) | G5: 74 | H5: 17 | I5: 97 | J5: 15 | K5: 44 | L5: 2 | M5: 20 | N5: 16
A6: 5 | B6: =G6*H6*3+I6*J6*3+K6*L6*3+M6*N6*3 | C6: 1970 | D6: =B6/C6 | E6: =IF(B6=0,"Нет",IF(AND(D6>=1.3,D6<=2),"Высокий",IF(AND(D6>=0.6,D6<1.3),"Средний","Низкий"))) | G6: 24 | H6: 15 | I6: 42 | J6: 3 | K6: 74 | L6: 15 | M6: 60 | N6: 3
A7: 6 | B7: =G7*H7*3+I7*J7*3+K7*L7*3+M7*N7*3 | C7: 4204 | D7: =B7/C7 | E7: =IF(B7=0,"Нет",IF(AND(D7>=1.3,D7<=2),"Высокий",IF(AND(D7>=0.6,D7<1.3),"Средний","Низкий"))) | G7: 115 | H7: 9 | I7: 19 | J7: 3
A8: 7 | B8: =G8*H8*3+I8*J8*3+K8*L8*3+M8*N8*3 | C8: 6328 | D8: =B8/C8 | E8: =IF(B8=0,"Нет",IF(AND(D8>=1.3,D8<=2),"Высокий",IF(AND(D8>=0.6,D8<1.3),"Средний","Низкий"))) | G8: 6 | H8: 17 | I8: 63 | J8: 15 | K8: 57 | L8: 3
A9: 8 | B9: =G9*H9*3+I9*J9*3+K9*L9*3+M9*N9*3 | C9: 3009 | D9: =B9/C9 | E9: =IF(B9=0,"Нет",IF(AND(D9>=1.3,D9<=2),"Высокий",IF(AND(D9>=0.6,D9<1.3),"Средний","Низкий"))) | G9: 78 | H9: 3 | I9: 7 | J9: 9 | K9: 65 | L9: 9 | M9: 6 | N9: 9
A10: 9 | B10: =G10*H10*3+I10*J10*3+K10*L10*3+M10*N10*3 | C10: 14584 | D10: =B10/C10 | E10: =IF(B10=0,"Нет",IF(AND(D10>=1.3,D10<=2),"Высокий",IF(AND(D10>=0.6,D10<1.3),"Средний","Низкий"))) | G10: 162 | H10: 9
A11: 10 | B11: =G11*H11*3+I11*J11*3+K11*L11*3+M11*N11*3 | C11: 1926 | D11: =B11/C11 | E11: =IF(B11=0,"Нет",IF(AND(D11>=1.3,D11<=2),"Высокий",IF(AND(D11>=0.6,D11<1.3),"Средний","Низкий"))) | G11: 6 | H11: 9 | I11: 40 | J11: 3 | K11: 32 | L11: 9 | M11: 4 | N11: 1
A12: 11 | B12: =G12*H12*3+I12*J12*3+K12*L12*3+M12*N12*3 | C12: 15274 | D12: =B12/C12 | E12: =IF(B12=0,"Нет",IF(AND(D12>=1.3,D12<=2),"Высокий",IF(AND(D12>=0.6,D12<1.3),"Средний","Низкий"))) | G12: 65 | H12: 9 | I12: 94 | J12: 9 | K12: 156 | L12: 9
A13: 12 | B13: =G13*H13*3+I13*J13*3+K13*L13*3+M13*N13*3 | C13: 5204 | D13: =B13/C13 | E13: =IF(B13=0,"Нет",IF(AND(D13>=1.3,D13<=2),"Высокий",IF(AND(D13>=0.6,D13<1.3),"Средний","Низкий"))) | G13: 12 | H13: 9
A14: 13 | B14: =G14*H14*3+I14*J14*3+K14*L14*3+M14*N14*3 | C14: 2673 | D14: =B14/C14 | E14: =IF(B14=0,"Нет",IF(AND(D14>=1.3,D14<=2),"Высокий",IF(AND(D14>=0.6,D14<1.3),"Средний","Низкий"))) | G14: 27 | H14: 9 | I14: 93 | J14: 9
A15: 14 | B15: =G15*H15*3+I15*J15*3+K15*L15*3+M15*N15*3 | C15: 9413 | D15: =B15/C15 | E15: =IF(B15=0,"Нет",IF(AND(D15>=1.3,D15<=2),"Высокий",IF(AND(D15>=0.6,D15<1.3),"Средний","Низкий"))) | G15: 93 | H15: 9 | I15: 43 | J15: 9
A16: 15 | B16: =G16*H16*3+I16*J16*3+K16*L16*3+M16*N16*3 | C16: 3968 | D16: =B16/C16 | E16: =IF(B16=0,"Нет",IF(AND(D16>=1.3,D16<=2),"Высокий",IF(AND(D16>=0.6,D16<1.3),"Средний","Низкий"))) | G16: 93 | H16: 9 | I16: 9 | J16: 9
A17: 16 | B17: =G17*H17*3+I17*J17*3+K17*L17*3+M17*N17*3 | C17: 12850 | D17: =B17/C17 | E17: =IF(B17=0,"Нет",IF(AND(D17>=1.3,D17<=2),"Высокий",IF(AND(D17>=0.6,D17<1.3),"Средний","Низкий"))) | G17: 62 | H17: 9 | I17: 109 | J17: 9 | K17: 29 | L17: 9 | M17: 106 | N17: 9
A18: 17 | B18: =G18*H18*3+I18*J18*3+K18*L18*3+M18*N18*3 | C18: 8223 | D18: =B18/C18 | E18: =IF(B18=0,"Нет",IF(AND(D18>=1.3,D18<=2),"Высокий",IF(AND(D18>=0.6,D18<1.3),"Средний","Низкий"))) | G18: 28 | H18: 9 | I18: 6 | J18: 9 | K18: 69 | L18: 9 | M18: 6 | N18: 9
A19: 18 | B19: =G19*H19*3+I19*J19*3+K19*L19*3+M19*N19*3 | C19: 1941 | D19: =B19/C19 | E19: =IF(B19=0,"Нет",IF(AND(D19>=1.3,D19<=2),"Высокий",IF(AND(D19>=0.6,D19<1.3),"Средний","Низкий"))) | G19: 115 | H19: 9
A20: 19 | B20: =G20*H20*3+I20*J20*3+K20*L20*3+M20*N20*3 | C20: 1345 | D20: =B20/C20 | E20: =IF(B20=0,"Нет",IF(AND(D20>=1.3,D20<=2),"Высокий",IF(AND(D20>=0.6,D20<1.3),"Средний","Низкий"))) | G20: 59 | H20: 9
A21: 20 | B21: =G21*H21*3+I21*J21*3+K21*L21*3+M21*N21*3 | C21: 4258 | D21: =B21/C21 | E21: =IF(B21=0,"Нет",IF(AND(D21>=1.3,D21<=2),"Высокий",IF(AND(D21>=0.6,D21<1.3),"Средний","Низкий"))) | G21: 42 | H21: 9 | I21: 45 | J21: 17
A22: 21 | B22: =G22*H22*3+I22*J22*3+K22*L22*3+M22*N22*3 | C22: 2551 | D22: =B22/C22 | E22: =IF(B22=0,"Нет",IF(AND(D22>=1.3,D22<=2),"Высокий",IF(AND(D22>=0.6,D22<1.3),"Средний","Низкий"))) | G22: 45 | H22: 17
A23: 22 | B23: =G23*H23*3+I23*J23*3+K23*L23*3+M23*N23*3 | C23: 2835 | D23: =B23/C23 | E23: =IF(B23=0,"Нет",IF(AND(D23>=1.3,D23<=2),"Высокий",IF(AND(D23>=0.6,D23<1.3),"Средний","Низкий"))) | G23: 92 | H23: 9
A24: 23 | B24: =G24*H24*3+I24*J24*3+K24*L24*3+M24*N24*3 | C24: 7393 | D24: =B24/C24 | E24: =IF(B24=0,"Нет",IF(AND(D24>=1.3,D24<=2),"Высокий",IF(AND(D24>=0.6,D24<1.3),"Средний","Низкий"))) | G24: 140 | H24: 9 | I24: 41 | J24: 9 | K24: 46 | L24: 3
A25: 24 | B25: =G25*H25*3+I25*J25*3+K25*L25*3+M25*N25*3 | C25: 4468 | D25: =B25/C25 | E25: =IF(B25=0,"Нет",IF(AND(D25>=1.3,D25<=2),"Высокий",IF(AND(D25>=0.6,D25<1.3),"Средний","Низкий"))) | G25: 67 | H25: 9 | I25: 57 | J25: 3
A26: 25 | B26: =G26*H26*3+I26*J26*3+K26*L26*3+M26*N26*3 | C26: 13528 | D26: =B26/C26 | E26: =IF(B26=0,"Нет",IF(AND(D26>=1.3,D26<=2),"Высокий",IF(AND(D26>=0.6,D26<1.3),"Средний","Низкий"))) | G26: 13 | H26: 3 | I26: 24 | J26: 9 | K26: 9 | L26: 3
A27: 26 | B27: =G27*H27*3+I27*J27*3+K27*L27*3+M27*N27*3 | C27: 3843 | D27: =B27/C27 | E27: =IF(B27=0,"Нет",IF(AND(D27>=1.3,D27<=2),"Высокий",IF(AND(D27>=0.6,D27<1.3),"Средний","Низкий"))) | G27: 34 | H27: 9 | I27: 55 | J27: 3
A28: 27 | B28: =G28*H28*3+I28*J28*3+K28*L28*3+M28*N28*3 | C28: 6162 | D28: =B28/C28 | E28: =IF(B28=0,"Нет",IF(AND(D28>=1.3,D28<=2),"Высокий",IF(AND(D28>=0.6,D28<1.3),"Средний","Низкий"))) | G28: 25 | H28: 1 | I28: 93 | J28: 9
A29: 28 | B29: =G29*H29*3+I29*J29*3+K29*L29*3+M29*N29*3 | C29: 5941 | D29: =B29/C29 | E29: =IF(B29=0,"Нет",IF(AND(D29>=1.3,D29<=2),"Высокий",IF(AND(D29>=0.6,D29<1.3),"Средний","Низкий"))) | G29: 93 | H29: 9 | I29: 17 | J29: 17 | O29: сумма длин фасадов 110 м, в листе замкнутости 156 м: проверить, все ли фасады внесены
A30: 29 | B30: =G30*H30*3+I30*J30*3+K30*L30*3+M30*N30*3 | C30: 4975 | D30: =B30/C30 | E30: =IF(B30=0,"Нет",IF(AND(D30>=1.3,D30<=2),"Высокий",IF(AND(D30>=0.6,D30<1.3),"Средний","Низкий"))) | G30: 93 | H30: 9
A31: 30 | B31: =G31*H31*3+I31*J31*3+K31*L31*3+M31*N31*3 | C31: 8390 | D31: =B31/C31 | E31: =IF(B31=0,"Нет",IF(AND(D31>=1.3,D31<=2),"Высокий",IF(AND(D31>=0.6,D31<1.3),"Средний","Низкий"))) | G31: 80 | H31: 9 | I31: 66 | J31: 3
A32: 31 | B32: =G32*H32*3+I32*J32*3+K32*L32*3+M32*N32*3 | C32: 4065 | D32: =B32/C32 | E32: =IF(B32=0,"Нет",IF(AND(D32>=1.3,D32<=2),"Высокий",IF(AND(D32>=0.6,D32<1.3),"Средний","Низкий"))) | G32: 70 | H32: 3 | O32: сумма длин фасадов 70 м, в листе замкнутости 106 м: проверить, все ли фасады внесены
A33: 32 | B33: =G33*H33*3+I33*J33*3+K33*L33*3+M33*N33*3 | C33: 9100 | D33: =B33/C33 | E33: =IF(B33=0,"Нет",IF(AND(D33>=1.3,D33<=2),"Высокий",IF(AND(D33>=0.6,D33<1.3),"Средний","Низкий"))) | G33: 70 | H33: 9 | I33: 70 | J33: 3
A34: 33 | B34: =G34*H34*3+I34*J34*3+K34*L34*3+M34*N34*3 | C34: 4720 | D34: =B34/C34 | E34: =IF(B34=0,"Нет",IF(AND(D34>=1.3,D34<=2),"Высокий",IF(AND(D34>=0.6,D34<1.3),"Средний","Низкий"))) | G34: 17 | H34: 3 | I34: 37 | J34: 9 | K34: 95 | L34: 9
A35: 34 | B35: =G35*H35*3+I35*J35*3+K35*L35*3+M35*N35*3 | C35: 13806 | D35: =B35/C35 | E35: =IF(B35=0,"Нет",IF(AND(D35>=1.3,D35<=2),"Высокий",IF(AND(D35>=0.6,D35<1.3),"Средний","Низкий"))) | G35: 95 | H35: 9 | I35: 13 | J35: 9 | K35: 7 | L35: 9 | M35: 6 | N35: 9
A36: 35 | B36: =G36*H36*3+I36*J36*3+K36*L36*3+M36*N36*3 | C36: 14117 | D36: =B36/C36 | E36: =IF(B36=0,"Нет",IF(AND(D36>=1.3,D36<=2),"Высокий",IF(AND(D36>=0.6,D36<1.3),"Средний","Низкий"))) | G36: 73 | H36: 3 | I36: 111 | J36: 9 | K36: 114 | L36: 9 | M36: 10 | N36: 1
A37: 36 | B37: =G37*H37*3+I37*J37*3+K37*L37*3+M37*N37*3 | C37: 15936 | D37: =B37/C37 | E37: =IF(B37=0,"Нет",IF(AND(D37>=1.3,D37<=2),"Высокий",IF(AND(D37>=0.6,D37<1.3),"Средний","Низкий"))) | G37: 111 | H37: 9 | I37: 73 | J37: 9 | K37: 118 | L37: 9 | M37: 7 | N37: 9
A38: 37 | B38: =G38*H38*3+I38*J38*3+K38*L38*3+M38*N38*3 | C38: 3550 | D38: =B38/C38 | E38: =IF(B38=0,"Нет",IF(AND(D38>=1.3,D38<=2),"Высокий",IF(AND(D38>=0.6,D38<1.3),"Средний","Низкий"))) | G38: 100 | H38: 9 | I38: 18 | J38: 9
A39: 38 | B39: =G39*H39*3+I39*J39*3+K39*L39*3+M39*N39*3 | C39: 3725 | D39: =B39/C39 | E39: =IF(B39=0,"Нет",IF(AND(D39>=1.3,D39<=2),"Высокий",IF(AND(D39>=0.6,D39<1.3),"Средний","Низкий"))) | G39: 88 | H39: 9 | I39: 5 | J39: 9
A40: 39 | B40: =G40*H40*3+I40*J40*3+K40*L40*3+M40*N40*3 | C40: 5164 | D40: =B40/C40 | E40: =IF(B40=0,"Нет",IF(AND(D40>=1.3,D40<=2),"Высокий",IF(AND(D40>=0.6,D40<1.3),"Средний","Низкий"))) | G40: 93 | H40: 9 | I40: 40 | J40: 14
...

Sheet Планировочные размеры
A1: Номер яч | B1: размер, м | C1: итог | D1: балл
A2: 1 | B2: 174 | C2: Некомфортная | D2: =IF(C2="Комфортная",1,0)
A3: 2 | B3: 91 | C3: Комфортная | D3: =IF(C3="Комфортная",1,0)
A4: 3 | B4: 154 | C4: Некомфортная | D4: =IF(C4="Комфортная",1,0)
A5: 4 | B5: 110 | C5: Комфортная | D5: =IF(C5="Комфортная",1,0)
A6: 5 | B6: 88 | C6: Комфортная | D6: =IF(C6="Комфортная",1,0)
A7: 6 | B7: 147 | C7: Некомфортная | D7: =IF(C7="Комфортная",1,0)
A8: 7 | B8: 139 | C8: Некомфортная | D8: =IF(C8="Комфортная",1,0)
A9: 8 | B9: 109 | C9: Комфортная | D9: =IF(C9="Комфортная",1,0)
A10: 9 | B10: 204 | C10: Некомфортная | D10: =IF(C10="Комфортная",1,0)
A11: 10 | B11: 60 | C11: Комфортная | D11: =IF(C11="Комфортная",1,0)
A12: 11 | B12: 187 | C12: Некомфортная | D12: =IF(C12="Комфортная",1,0)
A13: 12 | B13: 118 | C13: Комфортная | D13: =IF(C13="Комфортная",1,0)
... A53: 52 | B53: 91 | C53: Комфортная | D53: =IF(C53="Комфортная",1,0)

Sheet Степень замкнутости
A1: Номер яч | B1: длина фасадов | C1: Периметр ячеек | D1: коэф | E1: итог | F1: Комментарии
A2: 1 | B2: 167 | C2: 383 | D2: =B2/C2 | E2: =IF(D2>=0.65,"Высокий",IF(D2<=0.35,"Низкий","Средний")) | F2: длина забора
A3: 2 | B3: 80 | C3: 234 | D3: =B3/C3 | E3: =IF(D3>=0.65,"Высокий",IF(D3<=0.35,"Низкий","Средний"))
A4: 3 | B4: 167 | C4: 372 | D4: =B4/C4 | E4: =IF(D4>=0.65,"Высокий",IF(D4<=0.35,"Низкий","Средний")) | F4: длина забора
A5: 4 | B5: 234 | C5: 351 | D5: =B5/C5 | E5: =IF(D5>=0.65,"Высокий",IF(D5<=0.35,"Низкий","Средний"))
A6: 5 | B6: 193 | C6: 280 | D6: =B6/C6 | E6: =IF(D6>=0.65,"Высокий",IF(D6<=0.35,"Низкий","Средний"))
A7: 6 | B7: 137 | C7: 361 | D7: =B7/C7 | E7: =IF(D7>=0.65,"Высокий",IF(D7<=0.35,"Низкий","Средний"))
A8: 7 | B8: 135 | C8: 382 | D8: =B8/C8 | E8: =IF(D8>=0.65,"Высокий",IF(D8<=0.35,"Низкий","Средний"))
A9: 8 | B9: 156 | C9: 286 | D9: =B9/C9 | E9: =IF(D9>=0.65,"Высокий",IF(D9<=0.35,"Низкий","Средний")) | F9: было 81 м; исправлено по сумме длин из листа вертикальных пропорций
A10: 9 | B10: 166 | C10: 548 | D10: =B10/C10 | E10: =IF(D10>=0.65,"Высокий",IF(D10<=0.35,"Низкий","Средний"))
A11: 10 | B11: 68 | C11: 190 | D11: =B11/C11 | E11: =IF(D11>=0.65,"Высокий",IF(D11<=0.35,"Низкий","Средний"))
A12: 11 | B12: 319 | C12: 536 | D12: =B12/C12 | E12: =IF(D12>=0.65,"Высокий",IF(D12<=0.35,"Низкий","Средний"))
A13: 12 | B13: 12 | C13: 312 | D13: =B13/C13 | E13: =IF(D13>=0.65,"Высокий",IF(D13<=0.35,"Низкий","Средний"))
A14: 13 | B14: 127 | C14: 294 | D14: =B14/C14 | E14: =IF(D14>=0.65,"Высокий",IF(D14<=0.35,"Низкий","Средний"))
A15: 14 | B15: 148 | C15: 416 | D15: =B15/C15 | E15: =IF(D15>=0.65,"Высокий",IF(D15<=0.35,"Низкий","Средний"))
A16: 15 | B16: 112 | C16: 333 | D16: =B16/C16 | E16: =IF(D16>=0.65,"Высокий",IF(D16<=0.35,"Низкий","Средний"))
A17: 16 | B17: 319 | C17: 489 | D17: =B17/C17 | E17: =IF(D17>=0.65,"Высокий",IF(D17<=0.35,"Низкий","Средний"))
A18: 17 | B18: 137 | C18: 381 | D18: =B18/C18 | E18: =IF(D18>=0.65,"Высокий",IF(D18<=0.35,"Низкий","Средний"))
A19: 18 | B19: 112 | C19: 258 | D19: =B19/C19 | E19: =IF(D19>=0.65,"Высокий",IF(D19<=0.35,"Низкий","Средний"))
A20: 19 | B20: 62 | C20: 196 | D20: =B20/C20 | E20: =IF(D20>=0.65,"Высокий",IF(D20<=0.35,"Низкий","Средний"))
A21: 20 | B21: 105 | C21: 301 | D21: =B21/C21 | E21: =IF(D21>=0.65,"Высокий",IF(D21<=0.35,"Низкий","Средний"))
... A50: 49 | B50: 78 | C50: 218 | D50: =B50/C50 | E50: =IF(D50>=0.65,"Высокий",IF(D50<=0.35,"Низкий","Средний"))
A51: 50 | B51: 142 | C51: 361 | D51: =B51/C51 | E51: =IF(D51>=0.65,"Высокий",IF(D51<=0.35,"Низкий","Средний")) | F51: было 96 м; исправлено по сумме длин из листа вертикальных пропорций
A52: 51 | B52: 96 | C52: 269 | D52: =B52/C52 | E52: =IF(D52>=0.65,"Высокий",IF(D52<=0.35,"Низкий","Средний"))
A53: 52 | B53: 12 | C53: 221 | D53: =B53/C53 | E53: =IF(D53>=0.65,"Высокий",IF(D53<=0.35,"Низкий","Средний"))

Sheet Комфортность
A1: Номер яч | B1: Верт. пропорции | C1: План. размеры | D1: Степень замкнутости | E1: балл верт. | F1: балл план. | G1: балл замкн. | H1: Среднее | I1: итог | K1: порог | L1: 0.67
A2: 1 | B2: ='Вертикальные пропорции'!E2 | C2: ='Планировочные размеры'!C2 | D2: ='Степень замкнутости'!E2 | E2: =IF(B2="Высокий",1,IF(B2="Средний",0.5,0)) | F2: =IF(C2="Комфортная",1,0) | G2: =IF(D2="Высокий",1,IF(D2="Средний",0.5,0)) | H2: =AVERAGE(E2:G2) | I2: =IF(ROUND(H2,2)>=$L$1,"Комфортная","Некомфортная")
A3: 2 | B3: ='Вертикальные пропорции'!E3 | C3: ='Планировочные размеры'!C3 | D3: ='Степень замкнутости'!E3 | E3: =IF(B3="Высокий",1,IF(B3="Средний",0.5,0)) | F3: =IF(C3="Комфортная",1,0) | G3: =IF(D3="Высокий",1,IF(D3="Средний",0.5,0)) | H3: =AVERAGE(E3:G3) | I3: =IF(ROUND(H3,2)>=$L$1,"Комфортная","Некомфортная")
A4: 3 | B4: ='Вертикальные пропорции'!E4 | C4: ='Планировочные размеры'!C4 | D4: ='Степень замкнутости'!E4 | E4: =IF(B4="Высокий",1,IF(B4="Средний",0.5,0)) | F4: =IF(C4="Комфортная",1,0) | G4: =IF(D4="Высокий",1,IF(D4="Средний",0.5,0)) | H4: =AVERAGE(E4:G4) | I4: =IF(ROUND(H4,2)>=$L$1,"Комфортная","Некомфортная")
A5: 4 | B5: ='Вертикальные пропорции'!E5 | C5: ='Планировочные размеры'!C5 | D5: ='Степень замкнутости'!E5 | E5: =IF(B5="Высокий",1,IF(B5="Средний",0.5,0)) | F5: =IF(C5="Комфортная",1,0) | G5: =IF(D5="Высокий",1,IF(D5="Средний",0.5,0)) | H5: =AVERAGE(E5:G5) | I5: =IF(ROUND(H5,2)>=$L$1,"Комфортная","Некомфортная")
A6: 5 | B6: ='Вертикальные пропорции'!E6 | C6: ='Планировочные размеры'!C6 | D6: ='Степень замкнутости'!E6 | E6: =IF(B6="Высокий",1,IF(B6="Средний",0.5,0)) | F6: =IF(C6="Комфортная",1,0) | G6: =IF(D6="Высокий",1,IF(D6="Средний",0.5,0)) | H6: =AVERAGE(E6:G6) | I6: =IF(ROUND(H6,2)>=$L$1,"Комфортная","Некомфортная")
A7: 6 | B7: ='Вертикальные пропорции'!E7 | C7: ='Планировочные размеры'!C7 | D7: ='Степень замкнутости'!E7 | E7: =IF(B7="Высокий",1,IF(B7="Средний",0.5,0)) | F7: =IF(C7="Комфортная",1,0) | G7: =IF(D7="Высокий",1,IF(D7="Средний",0.5,0)) | H7: =AVERAGE(E7:G7) | I7: =IF(ROUND(H7,2)>=$L$1,"Комфортная","Некомфортная")
A8: 7 | B8: ='Вертикальные пропорции'!E8 | C8: ='Планировочные размеры'!C8 | D8: ='Степень замкнутости'!E8 | E8: =IF(B8="Высокий",1,IF(B8="Средний",0.5,0)) | F8: =IF(C8="Комфортная",1,0) | G8: =IF(D8="Высокий",1,IF(D8="Средний",0.5,0)) | H8: =AVERAGE(E8:G8) | I8: =IF(ROUND(H8,2)>=$L$1,"Комфортная","Некомфортная")
A9: 8 | B9: ='Вертикальные пропорции'!E9 | C9: ='Планировочные размеры'!C9 | D9: ='Степень замкнутости'!E9 | E9: =IF(B9="Высокий",1,IF(B9="Средний",0.5,0)) | F9: =IF(C9="Комфортная",1,0) | G9: =IF(D9="Высокий",1,IF(D9="Средний",0.5,0)) | H9: =AVERAGE(E9:G9) | I9: =IF(ROUND(H9,2)>=$L$1,"Комфортная","Некомфортная")
A10: 9 | B10: ='Вертикальные пропорции'!E10 | C10: ='Планировочные размеры'!C10 | D10: ='Степень замкнутости'!E10 | E10: =IF(B10="Высокий",1,IF(B10="Средний",0.5,0)) | F10: =IF(C10="Комфортная",1,0) | G10: =IF(D10="Высокий",1,IF(D10="Средний",0.5,0)) | H10: =AVERAGE(E10:G10) | I10: =IF(ROUND(H10,2)>=$L$1,"Комфортная","Некомфортная")
A11: 10 | B11: ='Вертикальные пропорции'!E11 | C11: ='Планировочные размеры'!C11 | D11: ='Степень замкнутости'!E11 | E11: =IF(B11="Высокий",1,IF(B11="Средний",0.5,0)) | F11: =IF(C11="Комфортная",1,0) | G11: =IF(D11="Высокий",1,IF(D11="Средний",0.5,0)) | H11: =AVERAGE(E11:G11) | I11: =IF(ROUND(H11,2)>=$L$1,"Комфортная","Некомфортная")
A12: 11 | B12: ='Вертикальные пропорции'!E12 | C12: ='Планировочные размеры'!C12 | D12: ='Степень замкнутости'!E12 | E12: =IF(B12="Высокий",1,IF(B12="Средний",0.5,0)) | F12: =IF(C12="Комфортная",1,0) | G12: =IF(D12="Высокий",1,IF(D12="Средний",0.5,0)) | H12: =AVERAGE(E12:G12) | I12: =IF(ROUND(H12,2)>=$L$1,"Комфортная","Некомфортная")
A13: 12 | B13: ='Вертикальные пропорции'!E13 | C13: ='Планировочные размеры'!C13 | D13: ='Степень замкнутости'!E13 | E13: =IF(B13="Высокий",1,IF(B13="Средний",0.5,0)) | F13: =IF(C13="Комфортная",1,0) | G13: =IF(D13="Высокий",1,IF(D13="Средний",0.5,0)) | H13: =AVERAGE(E13:G13) | I13: =IF(ROUND(H13,2)>=$L$1,"Комфортная","Некомфортная")
... A53: 52 | B53: ='Вертикальные пропорции'!E53 | C53: ='Планировочные размеры'!C53 | D53: ='Степень замкнутости'!E53 | E53: =IF(B53="Высокий",1,IF(B53="Средний",0.5,0)) | F53: =IF(C53="Комфортная",1,0) | G53: =IF(D53="Высокий",1,IF(D53="Средний",0.5,0)) | H53: =AVERAGE(E53:G53) | I53: =IF(ROUND(H53,2)>=$L$1,"Комфортная","Некомфортная")
